Workbook

Sheet prosjekter
A1: virksomhet | B1: status | C1: navn | D1: kostnadsramme_2026 | E1: aar_ferdig | F1: sluttkostnad | G1: stat_doc | H1: annen_finansiering | I1: landsdel_doc | J1: merknad | K1: stat_doc_brukes
A2: Statens vegvesen | B2: Ferdig | C2: E39 Hjartåberga | D2: 1031 | E2: 2014 | F2: 1018 | G2: 1018 | I2: Vestlandet | K2: =G2 -> 1018
A3: Statens vegvesen | B3: Ferdig | C3: Rv. 70 Oppdølstranda | D3: 1807 | E3: 2014 | F3: 1574 | G3: 1574 | I3: Vestlandet | K3: =G3 -> 1574
A4: Statens vegvesen | B4: Ferdig | C4: E18 Melleby–Momarken | D4: 1907 | E4: 2014 | F4: 2078 | G4: 1746 | H4: 333 | I4: Østlandet | K4: =G4 -> 1746
A5: Statens vegvesen | B5: Ferdig | C5: Rv. 7 Sokna–Ørgenvika | D5: 3213 | E5: 2014 | F5: 2736 | G5: 1296 | H5: 1440 | I5: Østlandet | K5: =G5 -> 1296
A6: Statens vegvesen | B6: Ferdig | C6: Rv. 2 Kongsvinger–Slomarka | D6: 3539 | E6: 2014 | F6: 3893 | G6: 1635 | H6: 2258 | I6: Østlandet | K6: =G6 -> 1635
A7: Statens vegvesen | B7: Ferdig | C7: E18 Gulli–Langåker | D7: 5221 | E7: 2014 | F7: 5172 | G7: 1545 | H7: 3627 | I7: Østlandet | K7: =G7 -> 1545
A8: Statens vegvesen | B8: Ferdig | C8: E16 Smedalsosen–Maristova–Borlaug | D8: 1681 | E8: 2014 | F8: 1167 | G8: 1167 | I8: Vestlandet/Østlandet | K8: =G8 -> 1167
A9: Statens vegvesen | B9: Ferdig | C9: E10 Solbjørnneset–Hamnøy | D9: 1106 | E9: 2014 | F9: 1347 | G9: 1347 | I9: Nord-Norge | K9: =G9 -> 1347
A10: Statens vegvesen | B10: Ferdig | C10: E18 Bjørvika | D10: 10408 | E10: 2015 | F10: 11609 | G10: 4556 | H10: 7053 | I10: Østlandet | K10: =G10 -> 4556
A11: Statens vegvesen | B11: Ferdig | C11: E6 Minnesund–Skaberud | D11: 9785 | E11: 2015 | F11: 10051 | G11: 2779 | H11: 7272 | I11: Østlandet | K11: =G11 -> 2779
A12: Statens vegvesen | B12: Ferdig | C12: E18 Sydhavna | D12: 1047 | E12: 2015 | F12: 1064 | G12: 250 | H12: 814 | I12: Østlandet | K12: =G12 -> 250
A13: Statens vegvesen | B13: Ferdig | C13: E136 Tresfjordbrua og Vågstrandstunnelen | D13: 2531 | E13: 2015 | F13: 2731 | G13: 1393 | H13: 1338 | I13: Vestlandet | K13: =G13 -> 1393
A14: Statens vegvesen | B14: Ferdig | C14: E6 Halselv–Møllnes | D14: 1622 | E14: 2016 | F14: 1380 | G14: 1380 | I14: Nord-Norge | K14: =G14 -> 1380
A15: Statens vegvesen | B15: Ferdig | C15: E18 Knapstad–Retvet | D15: 2391 | E15: 2016 | F15: 2460 | G15: 1308 | H15: 1152 | I15: Østlandet | K15: =G15 -> 1308
A16: Statens vegvesen | B16: Ferdig | C16: E6 Frya–Sjoa (Ringebu–Otta) | D16: 8216 | E16: 2016 | F16: 10043 | G16: 5737 | H16: 4306 | I16: Østlandet | K16: =G16 -> 5737
A17: Statens vegvesen | B17: Ferdig | C17: Rv. 4 Lunner grense–Jaren og Lynga sør | D17: 3531 | E17: 2017 | F17: 4558 | G17: 2287 | H17: 2271 | I17: Østlandet | K17: =G17 -> 2287
A18: Statens vegvesen | B18: Ferdig | C18: E18 Riksgrensen–Ørje | D18: 1289 | E18: 2017 | F18: 1468 | G18: 847 | H18: 621 | I18: Østlandet | K18: =G18 -> 847
A19: Statens vegvesen | B19: Ferdig | C19: E39 Hove–Sandved | D19: -898 | E19: 2017 | F19: 1145 | G19: 450 | H19: 694 | I19: Vestlandet | J19: Kostnadsramme «-898» gjengitt slik den står i dokumentet (sannsynlig feil) | K19: =G19 -> 450
A20: Statens vegvesen | B20: Ferdig | C20: E16 Varpe bru–Otrøsosen–Smedalsosen | D20: 2779 | E20: 2017 | F20: 2220 | G20: 2220 | I20: Østlandet | K20: =G20 -> 2220
A21: Statens vegvesen | B21: Ferdig | C21: E6 Indre Nordnes–Skardalen | D21: 1924 | E21: 2017 | F21: 1609 | G21: 1609 | I21: Nord-Norge | K21: =G21 -> 1609
A22: Statens vegvesen | B22: Ferdig | C22: E105 Elvenes–Hesseng | D22: 1099 | E22: 2017 | F22: 1099 | G22: 1099 | H22: 0 | I22: Nord-Norge | K22: =G22 -> 1099
A23: Statens vegvesen | B23: Ferdig | C23: E6 Sørkjosfjellet | D23: 1538 | E23: 2018 | F23: 1430 | G23: 1430 | H23: 0 | I23: Nord-Norge | K23: =G23 -> 1430
A24: Statens vegvesen | B24: Ferdig | C24: E6 Hålogalandsbrua inkl Trældal–Leirvik | D24: 5349 | E24: 2018 | F24: 5874 | G24: 4226 | H24: 1648 | I24: Nord-Norge | K24: =G24 -> 4226
A25: Statens vegvesen | B25: Ferdig | C25: E18 Bommestad–Sky | D25: 7774 | E25: 2018 | F25: 7044 | G25: 1795 | H25: 5248 | I25: Østlandet | K25: =G25 -> 1795
A26: Statens vegvesen | B26: Ferdig | C26: Rv. 36 Skyggestein–Skjelbredstrand | D26: 943 | E26: 2018 | F26: 1034 | G26: 1034 | I26: Østlandet | K26: =G26 -> 1034
A27: Statens vegvesen | B27: Ferdig | C27: Rv. 110 Simo–Ørebekk | D27: 1182 | E27: 2019 | F27: 1476 | G27: 915 | H27: 561 | I27: Østlandet | K27: =G27 -> 915
A28: Statens vegvesen | B28: Ferdig | C28: E134 Gvammen–Århus | D28: 3578 | E28: 2019 | F28: 3310 | G28: 3310 | I28: Østlandet | K28: =G28 -> 3310
A29: Statens vegvesen | B29: Ferdig | C29: E6 Helgeland nord | D29: 2892 | E29: 2019 | F29: 3293 | G29: 2684 | H29: 608 | I29: Nord-Norge | K29: =G29 -> 2684
A30: Statens vegvesen | B30: Ferdig | C30: E6 Jaktøya–Klett–Sentervegen | D30: 4332 | E30: 2019 | F30: 3839 | G30: 1427 | H30: 2412 | I30: Trøndelag | K30: =G30 -> 1427
A31: Statens vegvesen | B31: Ferdig | C31: Rv. 80 Hunstadmoen–Thallekrysset | D31: 3802 | E31: 2019 | F31: 3577 | G31: 923 | H31: 2654 | I31: Nord-Norge | K31: =G31 -> 923
A32: Statens vegvesen | B32: Ferdig | C32: E39 Bjørset–Skei | D32: 1263 | E32: 2019 | F32: 1053 | G32: 1053 | I32: Vestlandet | K32: =G32 -> 1053
A33: Statens vegvesen | B33: Ferdig | C33: E6 Tømmernes-, Forså-, Fagernes-, Larsberg-, Skardal- og Isfjelltunnelene | D33: 1272 | E33: 2019 | F33: 1167 | G33: 1167 | I33: Nord-Norge | K33: =G33 -> 1167
A34: Statens vegvesen | B34: Ferdig | C34: E6 Ekeberg- og Svardalstunnelene | D34: 991 | E34: 2019 | F34: 1085 | G34: 1085 | I34: Østlandet | K34: =G34 -> 1085
A35: Statens vegvesen | B35: Ferdig | C35: E16 Bagn–Bjørgo | D35: 2467 | E35: 2019 | F35: 2080 | G35: 1310 | H35: 770 | I35: Østlandet | K35: =G35 -> 1310
A36: Statens vegvesen | B36: Ferdig | C36: E16 Sandvika–Wøyen | D36: 6680 | E36: 2019 | F36: 5468 | G36: 1356 | H36: 4111 | I36: Østlandet | K36: =G36 -> 1356
A37: Statens vegvesen | B37: Ferdig | C37: E16 Øye–Eidsbru | D37: 1142 | E37: 2020 | F37: 1181 | G37: 1181 | I37: Østlandet | K37: =G37 -> 1181
A38: Statens vegvesen | B38: Ferdig | C38: Rv. 13 Ryfast | D38: 11342 | E38: 2020 | F38: 11709 | G38: 2653 | H38: 9056 | I38: Vestlandet | K38: =G38 -> 2653
A39: Statens vegvesen | B39: Ferdig | C39: E134 Damåsen–Saggrenda | D39: 7457 | E39: 2020 | F39: 6674 | G39: 2870 | H39: 3803 | I39: Østlandet | K39: =G39 -> 2870
A40: Statens vegvesen | B40: Ferdig | C40: E6 Vindåsliene–Korporalsbrua | D40: 2728 | E40: 2020 | F40: 2244 | G40: 1225 | H40: 1019 | I40: Trøndelag | K40: =G40 -> 1225
...

Sheet prosjekter_korrigert
A1: virksomhet | B1: status | C1: navn | D1: kostnadsramme_2026 | E1: aar_ferdig | F1: sluttkostnad | G1: stat_doc | H1: annen_finansiering | I1: landsdel_doc | J1: merknad | K1: merknad2 | L1: landsdel | M1: Faktor 2019-2026 | N1: MVA justering | O1: Geografisk korr | P1: stat
A2: Statens vegvesen | B2: Ferdig | C2: E39 Hjartåberga | D2: 1031 | E2: 2014 | F2: 1018 | G2: 1018 | I2: Vestlandet | L2: Vestlandet | M2: 1 | N2: 1 | O2: 1 | P2: =G2 -> 1018
A3: Statens vegvesen | B3: Ferdig | C3: Rv. 70 Oppdølstranda | D3: 1807 | E3: 2014 | F3: 1574 | G3: 1574 | I3: Vestlandet | L3: Vestlandet | M3: 1 | N3: 1 | O3: 1 | P3: =G3 -> 1574
A4: Statens vegvesen | B4: Ferdig | C4: E18 Melleby–Momarken | D4: 1907 | E4: 2014 | F4: 2078 | G4: 1746 | H4: 333 | I4: Østlandet | L4: Østlandet | M4: 1 | N4: 1 | O4: 1 | P4: =G4 -> 1746
A5: Statens vegvesen | B5: Ferdig | C5: Rv. 7 Sokna–Ørgenvika | D5: 3213 | E5: 2014 | F5: 2736 | G5: 1296 | H5: 1440 | I5: Østlandet | L5: Østlandet | M5: 1 | N5: 1 | O5: 1 | P5: =G5 -> 1296
A6: Statens vegvesen | B6: Ferdig | C6: Rv. 2 Kongsvinger–Slomarka | D6: 3539 | E6: 2014 | F6: 3893 | G6: 1635 | H6: 2258 | I6: Østlandet | L6: Østlandet | M6: 1 | N6: 1 | O6: 1 | P6: =G6 -> 1635
A7: Statens vegvesen | B7: Ferdig | C7: E18 Gulli–Langåker | D7: 5221 | E7: 2014 | F7: 5172 | G7: 1545 | H7: 3627 | I7: Østlandet | L7: Østlandet | M7: 1 | N7: 1 | O7: 1 | P7: =G7 -> 1545
A8: Statens vegvesen | B8: Ferdig | C8: E16 Smedalsosen–Maristova–Borlaug | D8: 1681 | E8: 2014 | F8: 1167 | G8: 1167 | I8: Vestlandet/Østlandet | K8: Ligger I all hovedsak Vestlandet | L8: Vestlandet | M8: 1 | N8: 1 | O8: 1 | P8: =G8 -> 1167
A9: Statens vegvesen | B9: Ferdig | C9: E10 Solbjørnneset–Hamnøy | D9: 1106 | E9: 2014 | F9: 1347 | G9: 1347 | I9: Nord-Norge | L9: Nord-Norge | M9: 1 | N9: 1 | O9: 1 | P9: =G9 -> 1347
A10: Statens vegvesen | B10: Ferdig | C10: E18 Bjørvika | D10: 10408 | E10: 2015 | F10: 11609 | G10: 4556 | H10: 7053 | I10: Østlandet | L10: Østlandet | M10: 1 | N10: 1 | O10: 1 | P10: =G10 -> 4556
A11: Statens vegvesen | B11: Ferdig | C11: E6 Minnesund–Skaberud | D11: 9785 | E11: 2015 | F11: 10051 | G11: 2779 | H11: 7272 | I11: Østlandet | L11: Østlandet | M11: 1 | N11: 1 | O11: 1 | P11: =G11 -> 2779
A12: Statens vegvesen | B12: Ferdig | C12: E18 Sydhavna | D12: 1047 | E12: 2015 | F12: 1064 | G12: 250 | H12: 814 | I12: Østlandet | L12: Østlandet | M12: 1 | N12: 1 | O12: 1 | P12: =G12 -> 250
A13: Statens vegvesen | B13: Ferdig | C13: E136 Tresfjordbrua og Vågstrandstunnelen | D13: 2531 | E13: 2015 | F13: 2731 | G13: 1393 | H13: 1338 | I13: Vestlandet | L13: Vestlandet | M13: 1 | N13: 1 | O13: 1 | P13: =G13 -> 1393
A14: Statens vegvesen | B14: Ferdig | C14: E6 Halselv–Møllnes | D14: 1622 | E14: 2016 | F14: 1380 | G14: 1380 | I14: Nord-Norge | L14: Nord-Norge | M14: 1 | N14: 1 | O14: 1 | P14: =G14 -> 1380
A15: Statens vegvesen | B15: Ferdig | C15: E18 Knapstad–Retvet | D15: 2391 | E15: 2016 | F15: 2460 | G15: 1308 | H15: 1152 | I15: Østlandet | L15: Østlandet | M15: 1 | N15: 1 | O15: 1 | P15: =G15 -> 1308
A16: Statens vegvesen | B16: Ferdig | C16: E6 Frya–Sjoa (Ringebu–Otta) | D16: 8216 | E16: 2016 | F16: 10043 | G16: 5737 | H16: 4306 | I16: Østlandet | L16: Østlandet | M16: 1 | N16: 1 | O16: 1 | P16: =G16 -> 5737
A17: Statens vegvesen | B17: Ferdig | C17: Rv. 4 Lunner grense–Jaren og Lynga sør | D17: 3531 | E17: 2017 | F17: 4558 | G17: 2287 | H17: 2271 | I17: Østlandet | L17: Østlandet | M17: 1 | N17: 1 | O17: 1 | P17: =G17 -> 2287
A18: Statens vegvesen | B18: Ferdig | C18: E18 Riksgrensen–Ørje | D18: 1289 | E18: 2017 | F18: 1468 | G18: 847 | H18: 621 | I18: Østlandet | L18: Østlandet | M18: 1 | N18: 1 | O18: 1 | P18: =G18 -> 847
A19: Statens vegvesen | B19: Ferdig | C19: E39 Hove–Sandved | D19: -898 | E19: 2017 | F19: 1145 | G19: 450 | H19: 694 | I19: Vestlandet | J19: Kostnadsramme «-898» gjengitt slik den står i dokumentet (sannsynlig feil) | L19: Vestlandet | M19: 1 | N19: 1 | O19: 1 | P19: =G19 -> 450
A20: Statens vegvesen | B20: Ferdig | C20: E16 Varpe bru–Otrøsosen–Smedalsosen | D20: 2779 | E20: 2017 | F20: 2220 | G20: 2220 | I20: Østlandet | K20: delt mellom Vestland og Østlandet | L20: Østlandet | M20: 1 | N20: 1 | O20: 0.6 | P20: =G20*O20 -> 1332
A21: Statens vegvesen | B21: Ferdig | C21: E16 Varpe bru–Otrøsosen–Smedalsosen | D21: 2779 | E21: 2017 | F21: 2220 | G21: 2220 | I21: Østlandet | K21: delt mellom Vestland og Østlandet | L21: Vestlandet | M21: 1 | N21: 1 | O21: 0.4 | P21: =G21*O21 -> 888
A22: Statens vegvesen | B22: Ferdig | C22: E6 Indre Nordnes–Skardalen | D22: 1924 | E22: 2017 | F22: 1609 | G22: 1609 | I22: Nord-Norge | L22: Nord-Norge | M22: 1 | N22: 1 | O22: 1 | P22: =G22 -> 1609
A23: Statens vegvesen | B23: Ferdig | C23: E105 Elvenes–Hesseng | D23: 1099 | E23: 2017 | F23: 1099 | G23: 1099 | H23: 0 | I23: Nord-Norge | L23: Nord-Norge | M23: 1 | N23: 1 | O23: 1 | P23: =G23 -> 1099
A24: Statens vegvesen | B24: Ferdig | C24: E6 Sørkjosfjellet | D24: 1538 | E24: 2018 | F24: 1430 | G24: 1430 | H24: 0 | I24: Nord-Norge | L24: Nord-Norge | M24: 1 | N24: 1 | O24: 1 | P24: =G24 -> 1430
A25: Statens vegvesen | B25: Ferdig | C25: E6 Hålogalandsbrua inkl Trældal–Leirvik | D25: 5349 | E25: 2018 | F25: 5874 | G25: 4226 | H25: 1648 | I25: Nord-Norge | L25: Nord-Norge | M25: 1 | N25: 1 | O25: 1 | P25: =G25 -> 4226
A26: Statens vegvesen | B26: Ferdig | C26: E18 Bommestad–Sky | D26: 7774 | E26: 2018 | F26: 7044 | G26: 1795 | H26: 5248 | I26: Østlandet | L26: Østlandet | M26: 1 | N26: 1 | O26: 1 | P26: =G26 -> 1795
A27: Statens vegvesen | B27: Ferdig | C27: Rv. 36 Skyggestein–Skjelbredstrand | D27: 943 | E27: 2018 | F27: 1034 | G27: 1034 | I27: Østlandet | L27: Østlandet | M27: 1 | N27: 1 | O27: 1 | P27: =G27 -> 1034
A28: Statens vegvesen | B28: Ferdig | C28: Rv. 110 Simo–Ørebekk | D28: 1182 | E28: 2019 | F28: 1476 | G28: 915 | H28: 561 | I28: Østlandet | L28: Østlandet | M28: 1 | N28: 1 | O28: 1 | P28: =G28 -> 915
A29: Statens vegvesen | B29: Ferdig | C29: E134 Gvammen–Århus | D29: 3578 | E29: 2019 | F29: 3310 | G29: 3310 | I29: Østlandet | L29: Østlandet | M29: 1 | N29: 1 | O29: 1 | P29: =G29 -> 3310
A30: Statens vegvesen | B30: Ferdig | C30: E6 Helgeland nord | D30: 2892 | E30: 2019 | F30: 3293 | G30: 2684 | H30: 608 | I30: Nord-Norge | L30: Nord-Norge | M30: 1 | N30: 1 | O30: 1 | P30: =G30 -> 2684
A31: Statens vegvesen | B31: Ferdig | C31: E6 Jaktøya–Klett–Sentervegen | D31: 4332 | E31: 2019 | F31: 3839 | G31: 1427 | H31: 2412 | I31: Trøndelag | L31: Trøndelag | M31: 1 | N31: 1 | O31: 1 | P31: =G31 -> 1427
A32: Statens vegvesen | B32: Ferdig | C32: Rv. 80 Hunstadmoen–Thallekrysset | D32: 3802 | E32: 2019 | F32: 3577 | G32: 923 | H32: 2654 | I32: Nord-Norge | L32: Nord-Norge | M32: 1 | N32: 1 | O32: 1 | P32: =G32 -> 923
A33: Statens vegvesen | B33: Ferdig | C33: E39 Bjørset–Skei | D33: 1263 | E33: 2019 | F33: 1053 | G33: 1053 | I33: Vestlandet | L33: Vestlandet | M33: 1 | N33: 1 | O33: 1 | P33: =G33 -> 1053
A34: Statens vegvesen | B34: Ferdig | C34: E6 Tømmernes-, Forså-, Fagernes-, Larsberg-, Skardal- og Isfjelltunnelene | D34: 1272 | E34: 2019 | F34: 1167 | G34: 1167 | I34: Nord-Norge | L34: Nord-Norge | M34: 1 | N34: 1 | O34: 1 | P34: =G34 -> 1167
A35: Statens vegvesen | B35: Ferdig | C35: E6 Ekeberg- og Svardalstunnelene | D35: 991 | E35: 2019 | F35: 1085 | G35: 1085 | I35: Østlandet | L35: Østlandet | M35: 1 | N35: 1 | O35: 1 | P35: =G35 -> 1085
A36: Statens vegvesen | B36: Ferdig | C36: E16 Bagn–Bjørgo | D36: 2467 | E36: 2019 | F36: 2080 | G36: 1310 | H36: 770 | I36: Østlandet | L36: Østlandet | M36: 1 | N36: 1 | O36: 1 | P36: =G36 -> 1310
A37: Statens vegvesen | B37: Ferdig | C37: E16 Sandvika–Wøyen | D37: 6680 | E37: 2019 | F37: 5468 | G37: 1356 | H37: 4111 | I37: Østlandet | L37: Østlandet | M37: 1 | N37: 1 | O37: 1 | P37: =G37 -> 1356
A38: Statens vegvesen | B38: Ferdig | C38: E16 Øye–Eidsbru | D38: 1142 | E38: 2020 | F38: 1181 | G38: 1181 | I38: Østlandet | L38: Østlandet | M38: 1 | N38: 1 | O38: 1 | P38: =G38 -> 1181
A39: Statens vegvesen | B39: Ferdig | C39: Rv. 13 Ryfast | D39: 11342 | E39: 2020 | F39: 11709 | G39: 2653 | H39: 9056 | I39: Vestlandet | L39: Vestlandet | M39: 1 | N39: 1 | O39: 1 | P39: =G39 -> 2653
A40: Statens vegvesen | B40: Ferdig | C40: E134 Damåsen–Saggrenda | D40: 7457 | E40: 2020 | F40: 6674 | G40: 2870 | H40: 3803 | I40: Østlandet | L40: Østlandet | M40: 1 | N40: 1 | O40: 1 | P40: =G40 -> 2870
...

Sheet Utregninger opprinnelig
A4: BEFOLKNINGSANDEL 2025 (SSB 06912)
A5: Østlandet | B5: 2870000
A6: Vestlandet | B6: 1420000
A7: Nord-Norge | B7: 480000
A8: Sørlandet | B8: 320000
A9: Trøndelag | B9: 480000
A10: Sum | B10: =SUM(B5:B9) -> 5570000
A16: FERDIGE PROSJEKTER 2014–2025 (GILLESVIK REPROD.)
A17: Landsdel | B17: Antall | C17: Stat (mrd) | D17: Andel % | E17: Per innbygger (KNOK)
A18: Østlandet | B18: =COUNTIFS(prosjekter!I$2:I$101,"Østlandet",prosjekter!B$2:B$101,"Ferdig")+2 -> 34 | C18: =SUMIFS(prosjekter!K$2:K$101,prosjekter!I$2:I$101,"Østlandet",prosjekter!B$2:B$101,"Ferdig")/1000 + 3.6 -> 145.071 | D18: =IFERROR(C18/$C$23,0) -> 0.61160039 | E18: =C18*1000000/$B$5 -> 50.547387
A19: Vestlandet | B19: =COUNTIFS(prosjekter!I$2:I$101,"Vestlandet",prosjekter!B$2:B$101,"Ferdig") -> 16 | C19: =SUMIFS(prosjekter!K$2:K$101,prosjekter!I$2:I$101,"Vestlandet",prosjekter!B$2:B$101,"Ferdig")/1000 -2.3 -> 34.264 | D19: =IFERROR(C19/$C$23,0) -> 0.14445255 | E19: =C19*1000000/$B$6 -> 24.129577 | L19: GILLESVIK
A20: Nord-Norge | B20: =COUNTIFS(prosjekter!I$2:I$101,"Nord-Norge",prosjekter!B$2:B$101,"Ferdig") -> 13 | C20: =SUMIFS(prosjekter!K$2:K$101,prosjekter!I$2:I$101,"Nord-Norge",prosjekter!B$2:B$101,"Ferdig")/1000 -> 28.278 | D20: =IFERROR(C20/$C23,0) -> 0.11921635 | E20: =C20*1000000/$B$7 -> 58.9125
A21: Sørlandet | B21: =COUNTIFS(prosjekter!I$2:I$101,"Sørlandet",prosjekter!B$2:B$101,"Ferdig") + 1 -> 3 | C21: =SUMIFS(prosjekter!K$2:K$101,prosjekter!I$2:I$101,"Sørlandet",prosjekter!B$2:B$101,"Ferdig")/1000 + 12.8 -> 20.452 | D21: =IFERROR(C21/$C$23,0) -> 0.08622296 | E21: =C21*1000000/$B$8 -> 63.9125
A22: Trøndelag | B22: =COUNTIFS(prosjekter!I$2:I$101,"Trøndelag",prosjekter!B$2:B$101,"Ferdig") + 1 -> 5 | C22: =SUMIFS(prosjekter!K$2:K$101,prosjekter!I$2:I$101,"Trøndelag",prosjekter!B$2:B$101,"Ferdig")/1000 + 2.9 -> 9.134 | D22: =IFERROR(C22/$C$23,0) -> 0.038507751 | E22: =C22*1000000/$B$9 -> 19.029167
A23: Sum | B23: =SUM(B16:B22) -> 71 | C23: =SUM(C18:C22) -> 237.199 | D23: =SUM(D18:D22) -> 1
A27: FERDIGE PROSJEKTER 2014–2025
A28: Landsdel | B28: Antall | C28: Stat (mrd) | D28: Andel % | E28: Per innbygger (KNOK)
A29: Østlandet | B29: =COUNTIFS(prosjekter!I$2:I$101,"Østlandet",prosjekter!B$2:B$101,"Ferdig") -> 32 | C29: =SUMIFS(prosjekter!K$2:K$101,prosjekter!I$2:I$101,"Østlandet",prosjekter!B$2:B$101,"Ferdig")/1000 -> 141.471 | D29: =IFERROR(C29/$C$34,0) -> 0.64246886 | E29: =C29*1000000/$B$5 -> 49.293031
A30: Vestlandet | B30: =COUNTIFS(prosjekter!I$2:I$101,"Vestlandet",prosjekter!B$2:B$101,"Ferdig") -> 16 | C30: =SUMIFS(prosjekter!K$2:K$101,prosjekter!I$2:I$101,"Vestlandet",prosjekter!B$2:B$101,"Ferdig")/1000 -> 36.564 | D30: =IFERROR(C30/$C$34,0) -> 0.1660498 | E30: =C30*1000000/$B$6 -> 25.749296
A31: Nord-Norge | B31: =COUNTIFS(prosjekter!I$2:I$101,"Nord-Norge",prosjekter!B$2:B$101,"Ferdig") -> 13 | C31: =SUMIFS(prosjekter!K$2:K$101,prosjekter!I$2:I$101,"Nord-Norge",prosjekter!B$2:B$101,"Ferdig")/1000 -> 28.278 | D31: =IFERROR(C31/$C$34,0) -> 0.1284202 | E31: =C31*1000000/$B$7 -> 58.9125
A32: Sørlandet | B32: =COUNTIFS(prosjekter!I$2:I$101,"Sørlandet",prosjekter!B$2:B$101,"Ferdig") -> 2 | C32: =SUMIFS(prosjekter!K$2:K$101,prosjekter!I$2:I$101,"Sørlandet",prosjekter!B$2:B$101,"Ferdig")/1000 -> 7.652 | D32: =IFERROR(C32/$C$34,0) -> 0.034750385 | E32: =C32*1000000/$B$8 -> 23.9125
A33: Trøndelag | B33: =COUNTIFS(prosjekter!I$2:I$101,"Trøndelag",prosjekter!B$2:B$101,"Ferdig") -> 4 | C33: =SUMIFS(prosjekter!K$2:K$101,prosjekter!I$2:I$101,"Trøndelag",prosjekter!B$2:B$101,"Ferdig")/1000 -> 6.234 | D33: =IFERROR(C33/$C$34,0) -> 0.028310755 | E33: =C33*1000000/$B$9 -> 12.9875
A34: Sum | B34: =SUM(B27:B33) -> 67 | C34: =SUM(C29:C33) -> 220.199 | D34: =SUM(D29:D33) -> 1
A39: ALLE PROSJEKTER 2014–2026+
A40: Landsdel | B40: Antall | C40: Stat (mrd) | D40: Andel % | E40: Per innbygger (KNOK)
A41: Østlandet | B41: =COUNTIFS(prosjekter!I$2:I$101,"Østlandet") -> 42 | C41: =SUMIFS(prosjekter!K$2:K$101,prosjekter!I$2:I$101,"Østlandet")/1000 -> 232.403 | D41: =IFERROR(C41/$C$46,0) -> 0.47625908 | E41: =C41*1000000/$B$5 -> 80.976655
A42: Vestlandet | B42: =COUNTIFS(prosjekter!I$2:I$101,"Vestlandet") -> 25 | C42: =SUMIFS(prosjekter!K$2:K$101,prosjekter!I$2:I$101,"Vestlandet")/1000 -> 111.911 | D42: =IFERROR(C42/$C$46,0) -> 0.2293371 | E42: =C42*1000000/$B$6 -> 78.810563
A43: Nord-Norge | B43: =COUNTIFS(prosjekter!I$2:I$101,"Nord-Norge") -> 19 | C43: =SUMIFS(prosjekter!K$2:K$101,prosjekter!I$2:I$101,"Nord-Norge")/1000 -> 71.787 | D43: =IFERROR(C43/$C$46,0) -> 0.14711174 | E43: =C43*1000000/$B$7 -> 149.55625
A44: Sørlandet | B44: =COUNTIFS(prosjekter!I$2:I$101,"Sørlandet") -> 5 | C44: =SUMIFS(prosjekter!K$2:K$101,prosjekter!I$2:I$101,"Sørlandet")/1000 -> 37.688 | D44: =IFERROR(C44/$C$46,0) -> 0.077233307 | E44: =C44*1000000/$B$8 -> 117.775
A45: Trøndelag | B45: =COUNTIFS(prosjekter!I$2:I$101,"Trøndelag") -> 7 | C45: =SUMIFS(prosjekter!K$2:K$101,prosjekter!I$2:I$101,"Trøndelag")/1000 -> 34.187 | D45: =IFERROR(C45/$C$46,0) -> 0.070058773 | E45: =C45*1000000/$B$9 -> 71.222917
A46: Sum | B46: =SUM(B39:B45) -> 98 | C46: =SUM(C41:C45) -> 487.976 | D46: =SUM(D41:D45) -> 1
A50: UNDER BYGGING
A51: Landsdel | B51: Antall | C51: Stat (mrd) | D51: Andel % | E51: Per innbygger (KNOK)
A52: Østlandet | B52: =COUNTIFS(prosjekter!I$2:I$101,"Østlandet",prosjekter!B$2:B$101,"Under bygging") -> 10 | C52: =SUMIFS(prosjekter!K$2:K$101,prosjekter!I$2:I$101,"Østlandet",prosjekter!B$2:B$101,"Under bygging")/1000 -> 90.932 | D52: =IFERROR(C52/$C$57,0) -> 0.33958107 | E52: =C52*1000000/$B$5 -> 31.683624
A53: Vestlandet | B53: =COUNTIFS(prosjekter!I$2:I$101,"Vestlandet",prosjekter!B$2:B$101,"Under bygging") -> 9 | C53: =SUMIFS(prosjekter!K$2:K$101,prosjekter!I$2:I$101,"Vestlandet",prosjekter!B$2:B$101,"Under bygging")/1000 -> 75.347 | D53: =IFERROR(C53/$C$57,0) -> 0.28137966 | E53: =C53*1000000/$B$6 -> 53.061268
A54: Nord-Norge | B54: =COUNTIFS(prosjekter!I$2:I$101,"Nord-Norge",prosjekter!B$2:B$101,"Under bygging") -> 6 | C54: =SUMIFS(prosjekter!K$2:K$101,prosjekter!I$2:I$101,"Nord-Norge",prosjekter!B$2:B$101,"Under bygging")/1000 -> 43.509 | D54: =IFERROR(C54/$C$57,0) -> 0.16248221 | E54: =C54*1000000/$B$7 -> 90.64375
A55: Sørlandet | B55: =COUNTIFS(prosjekter!I$2:I$101,"Sørlandet",prosjekter!B$2:B$101,"Ferdig") -> 2 | C55: =SUMIFS(prosjekter!K$2:K$101,prosjekter!I$2:I$101,"Sørlandet",prosjekter!B$2:B$101,"Under bygging")/1000 -> 30.036 | D55: =IFERROR(C55/$C$57,0) -> 0.11216796 | E55: =C55*1000000/$B$8 -> 93.8625
A56: Trøndelag | B56: =COUNTIFS(prosjekter!I$2:I$101,"Trøndelag",prosjekter!B$2:B$101,"Under bygging") -> 3 | C56: =SUMIFS(prosjekter!K$2:K$101,prosjekter!I$2:I$101,"Trøndelag",prosjekter!B$2:B$101,"Under bygging")/1000 -> 27.953 | D56: =IFERROR(C56/$C$57,0) -> 0.1043891 | E56: =C56*1000000/$B$9 -> 58.235417
A57: Sum | B57: =SUM(B50:B56) -> 30 | C57: =SUM(C52:C56) -> 267.777 | D57: =SUM(D52:D56) -> 1

Sheet Utregninger korrigert
A4: BEFOLKNINGSANDEL 2025 (SSB 06912)
A5: Østlandet | B5: 2870000
A6: Vestlandet | B6: 1420000
A7: Nord-Norge | B7: 480000
A8: Sørlandet | B8: 320000
A9: Trøndelag | B9: 480000
A10: Sum | B10: =SUM(B5:B9) -> 5570000
A13: AREAL
A14: Østlandet | B14: 94585
A15: Vestlandet | B15: 57694
A16: Nord-Norge | B16: 112951
A17: Sørlandet | B17: 16434
A18: Trøndelag | B18: 42201
A19: Sum | B19: =SUM(B14:B18) -> 323865
A25: FERDIGE PROSJEKTER 2014–2025
A26: Landsdel | B26: Antall | C26: Stat (mrd) | D26: Andel % | E26: Per innbygger (KNOK) | F26: Per Areal
A27: Østlandet | B27: =COUNTIFS(prosjekter_korrigert!L$2:L$102,"Østlandet",prosjekter_korrigert!B$2:B$102,"Ferdig") -> 32 | C27: =SUMIFS(prosjekter_korrigert!P$2:P$102,prosjekter_korrigert!L$2:L$102,"Østlandet",prosjekter_korrigert!B$2:B$102,"Ferdig")/1000 -> 159.6175 | D27: =IFERROR(C27/$C$32,0) -> 0.66344747 | E27: =C27*1000000/$B$5 -> 55.615854 | F27: =1000 * C27 / $B14 -> 1.6875562
A28: Vestlandet | B28: =COUNTIFS(prosjekter_korrigert!L$2:L$102,"Vestlandet",prosjekter_korrigert!B$2:B$102,"Ferdig") -> 18 | C28: =SUMIFS(prosjekter_korrigert!P$2:P$102,prosjekter_korrigert!L$2:L$102,"Vestlandet",prosjekter_korrigert!B$2:B$102,"Ferdig")/1000 -> 38.541 | D28: =IFERROR(C28/$C$32,0) -> 0.16019502 | E28: =C28*1000000/$B$6 -> 27.141549 | F28: =1000 * C28 / $B15 -> 0.6680244
A29: Nord-Norge | B29: =COUNTIFS(prosjekter_korrigert!L$2:L$102,"Nord-Norge",prosjekter_korrigert!B$2:B$102,"Ferdig") -> 13 | C29: =SUMIFS(prosjekter_korrigert!P$2:P$102,prosjekter_korrigert!L$2:L$102,"Nord-Norge",prosjekter_korrigert!B$2:B$102,"Ferdig")/1000 -> 28.278 | D29: =IFERROR(C29/$C$32,0) -> 0.11753703 | E29: =C29*1000000/$B$7 -> 58.9125 | F29: =1000 * C29 / $B16 -> 0.25035635
A30: Sørlandet | B30: =COUNTIFS(prosjekter_korrigert!L$2:L$102,"Sørlandet",prosjekter_korrigert!B$2:B$102,"Ferdig") -> 2 | C30: =SUMIFS(prosjekter_korrigert!P$2:P$102,prosjekter_korrigert!L$2:L$102,"Sørlandet",prosjekter_korrigert!B$2:B$102,"Ferdig")/1000 -> 7.652 | D30: =IFERROR(C30/$C$32,0) -> 0.03180541 | E30: =C30*1000000/$B$8 -> 23.9125 | F30: =1000 * C30 / $B17 -> 0.46562006
A31: Trøndelag | B31: =COUNTIFS(prosjekter_korrigert!L$2:L$102,"Trøndelag",prosjekter_korrigert!B$2:B$102,"Ferdig") -> 4 | C31: =SUMIFS(prosjekter_korrigert!P$2:P$102,prosjekter_korrigert!L$2:L$102,"Trøndelag",prosjekter_korrigert!B$2:B$102,"Ferdig")/1000 -> 6.4995 | D31: =IFERROR(C31/$C$32,0) -> 0.027015063 | E31: =C31*1000000/$B$9 -> 13.540625 | F31: =1000 * C31 / $B18 -> 0.15401294
A32: Sum | B32: =SUM(B25:B31) -> 69 | C32: =SUM(C27:C31) -> 240.588 | D32: =SUM(D27:D31) -> 1
A37: ALLE PROSJEKTER 2014–2026+
A38: Landsdel | B38: Antall | C38: Stat (mrd) | D38: Andel % | E38: Per innbygger (KNOK)
A39: Østlandet | B39: =COUNTIFS(prosjekter_korrigert!L$2:L$102,"Østlandet") -> 43 | C39: =SUMIFS(prosjekter_korrigert!P$2:P$102,prosjekter_korrigert!L$2:L$102,"Østlandet")/1000 -> 271.18075 | D39: =IFERROR(C39/$C$44,0) -> 0.51764869 | E39: =C39*1000000/$B$5 -> 94.488066
A40: Vestlandet | B40: =COUNTIFS(prosjekter_korrigert!L$2:L$102,"Vestlandet") -> 27 | C40: =SUMIFS(prosjekter_korrigert!P$2:P$102,prosjekter_korrigert!L$2:L$102,"Vestlandet")/1000 -> 113.888 | D40: =IFERROR(C40/$C$44,0) -> 0.21739734 | E40: =C40*1000000/$B$6 -> 80.202817
A41: Nord-Norge | B41: =COUNTIFS(prosjekter_korrigert!L$2:L$102,"Nord-Norge") -> 19 | C41: =SUMIFS(prosjekter_korrigert!P$2:P$102,prosjekter_korrigert!L$2:L$102,"Nord-Norge")/1000 -> 71.787 | D41: =IFERROR(C41/$C$44,0) -> 0.13703202 | E41: =C41*1000000/$B$7 -> 149.55625
A42: Sørlandet | B42: =COUNTIFS(prosjekter_korrigert!L$2:L$102,"Sørlandet") -> 4 | C42: =SUMIFS(prosjekter_korrigert!P$2:P$102,prosjekter_korrigert!L$2:L$102,"Sørlandet")/1000 -> 32.562 | D42: =IFERROR(C42/$C$44,0) -> 0.062156612 | E42: =C42*1000000/$B$8 -> 101.75625
A43: Trøndelag | B43: =COUNTIFS(prosjekter_korrigert!L$2:L$102,"Trøndelag") -> 7 | C43: =SUMIFS(prosjekter_korrigert!P$2:P$102,prosjekter_korrigert!L$2:L$102,"Trøndelag")/1000 -> 34.4525 | D43: =IFERROR(C43/$C$44,0) -> 0.06576533 | E43: =C43*1000000/$B$9 -> 71.776042
A44: Sum | B44: =SUM(B37:B43) -> 100 | C44: =SUM(C39:C43) -> 523.87025 | D44: =SUM(D39:D43) -> 1
A48: UNDER BYGGING
A49: Landsdel | B49: Antall | C49: Stat (mrd) | D49: Andel % | E49: Per innbygger (KNOK)
A50: Østlandet | B50: =COUNTIFS(prosjekter_korrigert!L$2:L$102,"Østlandet",prosjekter_korrigert!B$2:B$102,"Under bygging") -> 11 | C50: =SUMIFS(prosjekter_korrigert!P$2:P$102,prosjekter_korrigert!L$2:L$102,"Østlandet",prosjekter_korrigert!B$2:B$102,"Under bygging")/1000 -> 111.56325 | D50: =IFERROR(C50/$C$55,0) -> 0.39382365 | E50: =C50*1000000/$B$5 -> 38.872213
A51: Vestlandet | B51: =COUNTIFS(prosjekter_korrigert!L$2:L$102,"Vestlandet",prosjekter_korrigert!B$2:B$102,"Under bygging") -> 9 | C51: =SUMIFS(prosjekter_korrigert!P$2:P$102,prosjekter_korrigert!L$2:L$102,"Vestlandet",prosjekter_korrigert!B$2:B$102,"Under bygging")/1000 -> 75.347 | D51: =IFERROR(C51/$C$55,0) -> 0.26597854 | E51: =C51*1000000/$B$6 -> 53.061268
A52: Nord-Norge | B52: =COUNTIFS(prosjekter_korrigert!L$2:L$102,"Nord-Norge",prosjekter_korrigert!B$2:B$102,"Under bygging") -> 6 | C52: =SUMIFS(prosjekter_korrigert!P$2:P$102,prosjekter_korrigert!L$2:L$102,"Nord-Norge",prosjekter_korrigert!B$2:B$102,"Under bygging")/1000 -> 43.509 | D52: =IFERROR(C52/$C$55,0) -> 0.15358887 | E52: =C52*1000000/$B$7 -> 90.64375
A53: Sørlandet | B53: =COUNTIFS(prosjekter_korrigert!L$2:L$102,"Sørlandet",prosjekter_korrigert!B$2:B$102,"Ferdig") -> 2 | C53: =SUMIFS(prosjekter_korrigert!P$2:P$102,prosjekter_korrigert!L$2:L$102,"Sørlandet",prosjekter_korrigert!B$2:B$102,"Under bygging")/1000 -> 24.91 | D53: =IFERROR(C53/$C$55,0) -> 0.087933501 | E53: =C53*1000000/$B$8 -> 77.84375
A54: Trøndelag | B54: =COUNTIFS(prosjekter_korrigert!L$2:L$102,"Trøndelag",prosjekter_korrigert!B$2:B$102,"Under bygging") -> 3 | C54: =SUMIFS(prosjekter_korrigert!P$2:P$102,prosjekter_korrigert!L$2:L$102,"Trøndelag",prosjekter_korrigert!B$2:B$102,"Under bygging")/1000 -> 27.953 | D54: =IFERROR(C54/$C$55,0) -> 0.098675438 | E54: =C54*1000000/$B$9 -> 58.235417
A55: Sum | B55: =SUM(B48:B54) -> 31 | C55: =SUM(C50:C54) -> 283.28225 | D55: =SUM(D50:D54) -> 1

Sheet gillesvik
